[2024-09-23T09:12:23.975+0000] {taskinstance.py:1171} INFO - Dependencies all met for <TaskInstance: materlize_offline_to_online.materialize_task manual__2024-09-23T09:12:23.321026+00:00 [queued]>
[2024-09-23T09:12:24.115+0000] {taskinstance.py:1171} INFO - Dependencies all met for <TaskInstance: materlize_offline_to_online.materialize_task manual__2024-09-23T09:12:23.321026+00:00 [queued]>
[2024-09-23T09:12:24.115+0000] {taskinstance.py:1368} INFO - 
--------------------------------------------------------------------------------
[2024-09-23T09:12:24.115+0000] {taskinstance.py:1369} INFO - Starting attempt 1 of 1
[2024-09-23T09:12:24.115+0000] {taskinstance.py:1370} INFO - 
--------------------------------------------------------------------------------
[2024-09-23T09:12:24.131+0000] {taskinstance.py:1389} INFO - Executing <Task(DockerOperator): materialize_task> on 2024-09-23 09:12:23.321026+00:00
[2024-09-23T09:12:24.137+0000] {standard_task_runner.py:52} INFO - Started process 714 to run task
[2024-09-23T09:12:24.140+0000] {standard_task_runner.py:79} INFO - Running: ['***', 'tasks', 'run', 'materlize_offline_to_online', 'materialize_task', 'manual__2024-09-23T09:12:23.321026+00:00', '--job-id', '114', '--raw', '--subdir', 'DAGS_FOLDER/data_pipeline/materialize_offline_to_online.py', '--cfg-path', '/tmp/tmp6jdd_vil', '--error-file', '/tmp/tmp0y7l7blc']
[2024-09-23T09:12:24.142+0000] {standard_task_runner.py:80} INFO - Job 114: Subtask materialize_task
[2024-09-23T09:12:24.205+0000] {task_command.py:371} INFO - Running <TaskInstance: materlize_offline_to_online.materialize_task manual__2024-09-23T09:12:23.321026+00:00 [running]> on host 4f3194c3b428
[2024-09-23T09:12:24.298+0000] {taskinstance.py:1583} INFO - Exporting the following env vars:
AIRFLOW_CTX_DAG_OWNER=mlopsvn
AIRFLOW_CTX_DAG_ID=materlize_offline_to_online
AIRFLOW_CTX_TASK_ID=materialize_task
AIRFLOW_CTX_EXECUTION_DATE=2024-09-23T09:12:23.321026+00:00
AIRFLOW_CTX_TRY_NUMBER=1
AIRFLOW_CTX_DAG_RUN_ID=manual__2024-09-23T09:12:23.321026+00:00
[2024-09-23T09:12:24.314+0000] {docker.py:262} INFO - Starting docker container from image mlopsvn/mlops_crash_course/data_pipeline:latest
[2024-09-23T09:12:24.316+0000] {docker.py:273} WARNING - Using remote engine or docker-in-docker and mounting temporary volume from host is not supported. Falling back to `mount_tmp_dir=False` mode. You can set `mount_tmp_dir` parameter to False to disable mounting and remove the warning
[2024-09-23T09:12:25.456+0000] {docker.py:324} INFO - Traceback (most recent call last):
[2024-09-23T09:12:25.458+0000] {docker.py:324} INFO - File "/opt/venv/bin/feast", line 5, in <module>
    from feast.cli import cli
  File "/opt/venv/lib/python3.9/site-packages/feast/__init__.py", line 7, in <module>
    from feast.infra.offline_stores.bigquery_source import BigQuerySource
  File "/opt/venv/lib/python3.9/site-packages/feast/infra/offline_stores/bigquery_source.py", line 5, in <module>
    from feast import type_map
  File "/opt/venv/lib/python3.9/site-packages/feast/type_map.py", line 34, in <module>
    import pandas as pd
  File "/opt/venv/lib/python3.9/site-packages/pandas/__init__.py", line 22, in <module>
    from pandas.compat import is_numpy_dev as _is_numpy_dev  # pyright: ignore # noqa:F401
  File "/opt/venv/lib/python3.9/site-packages/pandas/compat/__init__.py", line 18, in <module>
    from pandas.compat.numpy import (
  File "/opt/venv/lib/python3.9/site-packages/pandas/compat/numpy/__init__.py", line 4, in <module>
    from pandas.util.version import Version
  File "/opt/venv/lib/python3.9/site-packages/pandas/util/__init__.py", line 2, in <module>
    from pandas.util._decorators import (  # noqa:F401
  File "/opt/venv/lib/python3.9/site-packages/pandas/util/_decorators.py", line 14, in <module>
    from pandas._libs.properties import cache_readonly
  File "/opt/venv/lib/python3.9/site-packages/pandas/_libs/__init__.py", line 13, in <module>
    from pandas._libs.interval import Interval
  File "pandas/_libs/interval.pyx", line 1, in init pandas._libs.interval
ValueError: numpy.dtype size changed, may indicate binary incompatibility. Expected 96 from C header, got 88 from PyObject
[2024-09-23T09:12:25.671+0000] {taskinstance.py:1902} ERROR - Task failed with exception
Traceback (most recent call last):
  File "/home/airflow/.local/lib/python3.7/site-packages/docker/api/client.py", line 268, in _raise_for_status
    response.raise_for_status()
  File "/home/airflow/.local/lib/python3.7/site-packages/requests/models.py", line 1022, in raise_for_status
    raise HTTPError(http_error_msg, response=self)
requests.exceptions.HTTPError: 400 Client Error: Bad Request for url: http+docker://localhost/v1.47/containers/create

The above exception was the direct cause of the following exception:

Traceback (most recent call last):
  File "/home/airflow/.local/lib/python3.7/site-packages/airflow/providers/docker/operators/docker.py", line 269, in _run_image
    return self._run_image_with_mounts(self.mounts + [tmp_mount], add_tmp_variable=True)
  File "/home/airflow/.local/lib/python3.7/site-packages/airflow/providers/docker/operators/docker.py", line 314, in _run_image_with_mounts
    tty=self.tty,
  File "/home/airflow/.local/lib/python3.7/site-packages/docker/api/container.py", line 431, in create_container
    return self.create_container_from_config(config, name, platform)
  File "/home/airflow/.local/lib/python3.7/site-packages/docker/api/container.py", line 448, in create_container_from_config
    return self._result(res, True)
  File "/home/airflow/.local/lib/python3.7/site-packages/docker/api/client.py", line 274, in _result
    self._raise_for_status(response)
  File "/home/airflow/.local/lib/python3.7/site-packages/docker/api/client.py", line 270, in _raise_for_status
    raise create_api_error_from_http_exception(e) from e
  File "/home/airflow/.local/lib/python3.7/site-packages/docker/errors.py", line 39, in create_api_error_from_http_exception
    raise cls(e, response=response, explanation=explanation) from e
docker.errors.APIError: 400 Client Error for http+docker://localhost/v1.47/containers/create: Bad Request ("invalid mount config for type "bind": bind source path does not exist: /tmp/airflowtmp_x13jz4v")

During handling of the above exception, another exception occurred:

Traceback (most recent call last):
  File "/home/airflow/.local/lib/python3.7/site-packages/airflow/providers/docker/operators/docker.py", line 400, in execute
    return self._run_image()
  File "/home/airflow/.local/lib/python3.7/site-packages/airflow/providers/docker/operators/docker.py", line 278, in _run_image
    return self._run_image_with_mounts(self.mounts, add_tmp_variable=False)
  File "/home/airflow/.local/lib/python3.7/site-packages/airflow/providers/docker/operators/docker.py", line 329, in _run_image_with_mounts
    raise AirflowException(f'Docker container failed: {repr(result)} lines {joined_log_lines}')
airflow.exceptions.AirflowException: Docker container failed: {'StatusCode': 1} lines Traceback (most recent call last):
File "/opt/venv/bin/feast", line 5, in <module>
    from feast.cli import cli
  File "/opt/venv/lib/python3.9/site-packages/feast/__init__.py", line 7, in <module>
    from feast.infra.offline_stores.bigquery_source import BigQuerySource
  File "/opt/venv/lib/python3.9/site-packages/feast/infra/offline_stores/bigquery_source.py", line 5, in <module>
    from feast import type_map
  File "/opt/venv/lib/python3.9/site-packages/feast/type_map.py", line 34, in <module>
    import pandas as pd
  File "/opt/venv/lib/python3.9/site-packages/pandas/__init__.py", line 22, in <module>
    from pandas.compat import is_numpy_dev as _is_numpy_dev  # pyright: ignore # noqa:F401
  File "/opt/venv/lib/python3.9/site-packages/pandas/compat/__init__.py", line 18, in <module>
    from pandas.compat.numpy import (
  File "/opt/venv/lib/python3.9/site-packages/pandas/compat/numpy/__init__.py", line 4, in <module>
    from pandas.util.version import Version
  File "/opt/venv/lib/python3.9/site-packages/pandas/util/__init__.py", line 2, in <module>
    from pandas.util._decorators import (  # noqa:F401
  File "/opt/venv/lib/python3.9/site-packages/pandas/util/_decorators.py", line 14, in <module>
    from pandas._libs.properties import cache_readonly
  File "/opt/venv/lib/python3.9/site-packages/pandas/_libs/__init__.py", line 13, in <module>
    from pandas._libs.interval import Interval
  File "pandas/_libs/interval.pyx", line 1, in init pandas._libs.interval
ValueError: numpy.dtype size changed, may indicate binary incompatibility. Expected 96 from C header, got 88 from PyObject
[2024-09-23T09:12:25.676+0000] {taskinstance.py:1412} INFO - Marking task as FAILED. dag_id=materlize_offline_to_online, task_id=materialize_task, execution_date=20240923T091223, start_date=20240923T091223, end_date=20240923T091225
[2024-09-23T09:12:25.688+0000] {standard_task_runner.py:97} ERROR - Failed to execute job 114 for task materialize_task (Docker container failed: {'StatusCode': 1} lines Traceback (most recent call last):
File "/opt/venv/bin/feast", line 5, in <module>
    from feast.cli import cli
  File "/opt/venv/lib/python3.9/site-packages/feast/__init__.py", line 7, in <module>
    from feast.infra.offline_stores.bigquery_source import BigQuerySource
  File "/opt/venv/lib/python3.9/site-packages/feast/infra/offline_stores/bigquery_source.py", line 5, in <module>
    from feast import type_map
  File "/opt/venv/lib/python3.9/site-packages/feast/type_map.py", line 34, in <module>
    import pandas as pd
  File "/opt/venv/lib/python3.9/site-packages/pandas/__init__.py", line 22, in <module>
    from pandas.compat import is_numpy_dev as _is_numpy_dev  # pyright: ignore # noqa:F401
  File "/opt/venv/lib/python3.9/site-packages/pandas/compat/__init__.py", line 18, in <module>
    from pandas.compat.numpy import (
  File "/opt/venv/lib/python3.9/site-packages/pandas/compat/numpy/__init__.py", line 4, in <module>
    from pandas.util.version import Version
  File "/opt/venv/lib/python3.9/site-packages/pandas/util/__init__.py", line 2, in <module>
    from pandas.util._decorators import (  # noqa:F401
  File "/opt/venv/lib/python3.9/site-packages/pandas/util/_decorators.py", line 14, in <module>
    from pandas._libs.properties import cache_readonly
  File "/opt/venv/lib/python3.9/site-packages/pandas/_libs/__init__.py", line 13, in <module>
    from pandas._libs.interval import Interval
  File "pandas/_libs/interval.pyx", line 1, in init pandas._libs.interval
ValueError: numpy.dtype size changed, may indicate binary incompatibility. Expected 96 from C header, got 88 from PyObject; 714)
[2024-09-23T09:12:25.716+0000] {local_task_job.py:156} INFO - Task exited with return code 1
[2024-09-23T09:12:25.781+0000] {local_task_job.py:279} INFO - 0 downstream tasks scheduled from follow-on schedule check
