[2024-09-23T08:57:29.958+0000] {taskinstance.py:1171} INFO - Dependencies all met for <TaskInstance: db_to_offline_store.ingest_task manual__2024-09-23T08:57:28.797602+00:00 [queued]>
[2024-09-23T08:57:29.968+0000] {taskinstance.py:1171} INFO - Dependencies all met for <TaskInstance: db_to_offline_store.ingest_task manual__2024-09-23T08:57:28.797602+00:00 [queued]>
[2024-09-23T08:57:29.969+0000] {taskinstance.py:1368} INFO - 
--------------------------------------------------------------------------------
[2024-09-23T08:57:29.969+0000] {taskinstance.py:1369} INFO - Starting attempt 1 of 1
[2024-09-23T08:57:29.969+0000] {taskinstance.py:1370} INFO - 
--------------------------------------------------------------------------------
[2024-09-23T08:57:29.981+0000] {taskinstance.py:1389} INFO - Executing <Task(DockerOperator): ingest_task> on 2024-09-23 08:57:28.797602+00:00
[2024-09-23T08:57:29.987+0000] {standard_task_runner.py:52} INFO - Started process 287 to run task
[2024-09-23T08:57:29.989+0000] {standard_task_runner.py:79} INFO - Running: ['***', 'tasks', 'run', 'db_to_offline_store', 'ingest_task', 'manual__2024-09-23T08:57:28.797602+00:00', '--job-id', '104', '--raw', '--subdir', 'DAGS_FOLDER/data_pipeline/db_to_offline_store.py', '--cfg-path', '/tmp/tmpmh8i6hc6', '--error-file', '/tmp/tmpjfzphn_5']
[2024-09-23T08:57:29.990+0000] {standard_task_runner.py:80} INFO - Job 104: Subtask ingest_task
[2024-09-23T08:57:30.045+0000] {task_command.py:371} INFO - Running <TaskInstance: db_to_offline_store.ingest_task manual__2024-09-23T08:57:28.797602+00:00 [running]> on host 5c0ab49f36ea
[2024-09-23T08:57:30.117+0000] {taskinstance.py:1583} INFO - Exporting the following env vars:
AIRFLOW_CTX_DAG_OWNER=mlopsvn
AIRFLOW_CTX_DAG_ID=db_to_offline_store
AIRFLOW_CTX_TASK_ID=ingest_task
AIRFLOW_CTX_EXECUTION_DATE=2024-09-23T08:57:28.797602+00:00
AIRFLOW_CTX_TRY_NUMBER=1
AIRFLOW_CTX_DAG_RUN_ID=manual__2024-09-23T08:57:28.797602+00:00
[2024-09-23T08:57:30.121+0000] {taskinstance.py:1902} ERROR - Task failed with exception
Traceback (most recent call last):
  File "/home/airflow/.local/lib/python3.7/site-packages/urllib3/connectionpool.py", line 710, in urlopen
    chunked=chunked,
  File "/home/airflow/.local/lib/python3.7/site-packages/urllib3/connectionpool.py", line 398, in _make_request
    conn.request(method, url, **httplib_request_kw)
  File "/usr/local/lib/python3.7/http/client.py", line 1281, in request
    self._send_request(method, url, body, headers, encode_chunked)
  File "/usr/local/lib/python3.7/http/client.py", line 1327, in _send_request
    self.endheaders(body, encode_chunked=encode_chunked)
  File "/usr/local/lib/python3.7/http/client.py", line 1276, in endheaders
    self._send_output(message_body, encode_chunked=encode_chunked)
  File "/usr/local/lib/python3.7/http/client.py", line 1036, in _send_output
    self.send(msg)
  File "/usr/local/lib/python3.7/http/client.py", line 976, in send
    self.connect()
  File "/home/airflow/.local/lib/python3.7/site-packages/docker/transport/unixconn.py", line 30, in connect
    sock.connect(self.unix_socket)
PermissionError: [Errno 13] Permission denied

During handling of the above exception, another exception occurred:

Traceback (most recent call last):
  File "/home/airflow/.local/lib/python3.7/site-packages/requests/adapters.py", line 499, in send
    timeout=timeout,
  File "/home/airflow/.local/lib/python3.7/site-packages/urllib3/connectionpool.py", line 788, in urlopen
    method, url, error=e, _pool=self, _stacktrace=sys.exc_info()[2]
  File "/home/airflow/.local/lib/python3.7/site-packages/urllib3/util/retry.py", line 550, in increment
    raise six.reraise(type(error), error, _stacktrace)
  File "/home/airflow/.local/lib/python3.7/site-packages/urllib3/packages/six.py", line 769, in reraise
    raise value.with_traceback(tb)
  File "/home/airflow/.local/lib/python3.7/site-packages/urllib3/connectionpool.py", line 710, in urlopen
    chunked=chunked,
  File "/home/airflow/.local/lib/python3.7/site-packages/urllib3/connectionpool.py", line 398, in _make_request
    conn.request(method, url, **httplib_request_kw)
  File "/usr/local/lib/python3.7/http/client.py", line 1281, in request
    self._send_request(method, url, body, headers, encode_chunked)
  File "/usr/local/lib/python3.7/http/client.py", line 1327, in _send_request
    self.endheaders(body, encode_chunked=encode_chunked)
  File "/usr/local/lib/python3.7/http/client.py", line 1276, in endheaders
    self._send_output(message_body, encode_chunked=encode_chunked)
  File "/usr/local/lib/python3.7/http/client.py", line 1036, in _send_output
    self.send(msg)
  File "/usr/local/lib/python3.7/http/client.py", line 976, in send
    self.connect()
  File "/home/airflow/.local/lib/python3.7/site-packages/docker/transport/unixconn.py", line 30, in connect
    sock.connect(self.unix_socket)
urllib3.exceptions.ProtocolError: ('Connection aborted.', PermissionError(13, 'Permission denied'))

During handling of the above exception, another exception occurred:

Traceback (most recent call last):
  File "/home/airflow/.local/lib/python3.7/site-packages/docker/api/client.py", line 214, in _retrieve_server_version
    return self.version(api_version=False)["ApiVersion"]
  File "/home/airflow/.local/lib/python3.7/site-packages/docker/api/daemon.py", line 181, in version
    return self._result(self._get(url), json=True)
  File "/home/airflow/.local/lib/python3.7/site-packages/docker/utils/decorators.py", line 46, in inner
    return f(self, *args, **kwargs)
  File "/home/airflow/.local/lib/python3.7/site-packages/docker/api/client.py", line 237, in _get
    return self.get(url, **self._set_request_timeout(kwargs))
  File "/home/airflow/.local/lib/python3.7/site-packages/requests/sessions.py", line 600, in get
    return self.request("GET", url, **kwargs)
  File "/home/airflow/.local/lib/python3.7/site-packages/requests/sessions.py", line 587, in request
    resp = self.send(prep, **send_kwargs)
  File "/home/airflow/.local/lib/python3.7/site-packages/requests/sessions.py", line 701, in send
    r = adapter.send(request, **kwargs)
  File "/home/airflow/.local/lib/python3.7/site-packages/requests/adapters.py", line 547, in send
    raise ConnectionError(err, request=request)
requests.exceptions.ConnectionError: ('Connection aborted.', PermissionError(13, 'Permission denied'))

During handling of the above exception, another exception occurred:

Traceback (most recent call last):
  File "/home/airflow/.local/lib/python3.7/site-packages/airflow/providers/docker/operators/docker.py", line 377, in execute
    self.cli = self._get_cli()
  File "/home/airflow/.local/lib/python3.7/site-packages/airflow/providers/docker/operators/docker.py", line 408, in _get_cli
    base_url=self.docker_url, version=self.api_version, tls=tls_config, timeout=self.timeout
  File "/home/airflow/.local/lib/python3.7/site-packages/docker/api/client.py", line 197, in __init__
    self._version = self._retrieve_server_version()
  File "/home/airflow/.local/lib/python3.7/site-packages/docker/api/client.py", line 222, in _retrieve_server_version
    f'Error while fetching server API version: {e}'
docker.errors.DockerException: Error while fetching server API version: ('Connection aborted.', PermissionError(13, 'Permission denied'))
[2024-09-23T08:57:30.134+0000] {taskinstance.py:1412} INFO - Marking task as FAILED. dag_id=db_to_offline_store, task_id=ingest_task, execution_date=20240923T085728, start_date=20240923T085729, end_date=20240923T085730
[2024-09-23T08:57:30.144+0000] {standard_task_runner.py:97} ERROR - Failed to execute job 104 for task ingest_task (Error while fetching server API version: ('Connection aborted.', PermissionError(13, 'Permission denied')); 287)
[2024-09-23T08:57:30.161+0000] {local_task_job.py:156} INFO - Task exited with return code 1
[2024-09-23T08:57:30.202+0000] {local_task_job.py:279} INFO - 0 downstream tasks scheduled from follow-on schedule check
