[2024-09-23T09:12:23.966+0000] {taskinstance.py:1171} INFO - Dependencies all met for <TaskInstance: materlize_offline_to_online.materialize_task scheduled__2022-01-01T00:00:00+00:00 [queued]>
[2024-09-23T09:12:24.109+0000] {taskinstance.py:1171} INFO - Dependencies all met for <TaskInstance: materlize_offline_to_online.materialize_task scheduled__2022-01-01T00:00:00+00:00 [queued]>
[2024-09-23T09:12:24.109+0000] {taskinstance.py:1368} INFO - 
--------------------------------------------------------------------------------
[2024-09-23T09:12:24.110+0000] {taskinstance.py:1369} INFO - Starting attempt 1 of 1
[2024-09-23T09:12:24.110+0000] {taskinstance.py:1370} INFO - 
--------------------------------------------------------------------------------
[2024-09-23T09:12:24.130+0000] {taskinstance.py:1389} INFO - Executing <Task(DockerOperator): materialize_task> on 2022-01-01 00:00:00+00:00
[2024-09-23T09:12:24.137+0000] {standard_task_runner.py:52} INFO - Started process 713 to run task
[2024-09-23T09:12:24.140+0000] {standard_task_runner.py:79} INFO - Running: ['***', 'tasks', 'run', 'materlize_offline_to_online', 'materialize_task', 'scheduled__2022-01-01T00:00:00+00:00', '--job-id', '113', '--raw', '--subdir', 'DAGS_FOLDER/data_pipeline/materialize_offline_to_online.py', '--cfg-path', '/tmp/tmp3sxi7r06', '--error-file', '/tmp/tmp4h6uowu1']
[2024-09-23T09:12:24.141+0000] {standard_task_runner.py:80} INFO - Job 113: Subtask materialize_task
[2024-09-23T09:12:24.205+0000] {task_command.py:371} INFO - Running <TaskInstance: materlize_offline_to_online.materialize_task scheduled__2022-01-01T00:00:00+00:00 [running]> on host 4f3194c3b428
[2024-09-23T09:12:24.298+0000] {taskinstance.py:1583} INFO - Exporting the following env vars:
AIRFLOW_CTX_DAG_OWNER=mlopsvn
AIRFLOW_CTX_DAG_ID=materlize_offline_to_online
AIRFLOW_CTX_TASK_ID=materialize_task
AIRFLOW_CTX_EXECUTION_DATE=2022-01-01T00:00:00+00:00
AIRFLOW_CTX_TRY_NUMBER=1
AIRFLOW_CTX_DAG_RUN_ID=scheduled__2022-01-01T00:00:00+00:00
[2024-09-23T09:12:24.314+0000] {docker.py:262} INFO - Starting docker container from image mlopsvn/mlops_crash_course/data_pipeline:latest
[2024-09-23T09:12:24.316+0000] {docker.py:273} WARNING - Using remote engine or docker-in-docker and mounting temporary volume from host is not supported. Falling back to `mount_tmp_dir=False` mode. You can set `mount_tmp_dir` parameter to False to disable mounting and remove the warning
[2024-09-23T09:12:25.455+0000] {docker.py:324} INFO - Traceback (most recent call last):
  File "/opt/venv/bin/feast", line 5, in <module>
[2024-09-23T09:12:25.455+0000] {docker.py:324} INFO - from feast.cli import cli
[2024-09-23T09:12:25.456+0000] {docker.py:324} INFO - File "/opt/venv/lib/python3.9/site-packages/feast/__init__.py", line 7, in <module>
[2024-09-23T09:12:25.456+0000] {docker.py:324} INFO - from feast.infra.offline_stores.bigquery_source import BigQuerySource
  File "/opt/venv/lib/python3.9/site-packages/feast/infra/offline_stores/bigquery_source.py", line 5, in <module>
[2024-09-23T09:12:25.456+0000] {docker.py:324} INFO - from feast import type_map
  File "/opt/venv/lib/python3.9/site-packages/feast/type_map.py", line 34, in <module>
[2024-09-23T09:12:25.457+0000] {docker.py:324} INFO - import pandas as pd
  File "/opt/venv/lib/python3.9/site-packages/pandas/__init__.py", line 22, in <module>
[2024-09-23T09:12:25.457+0000] {docker.py:324} INFO - from pandas.compat import is_numpy_dev as _is_numpy_dev  # pyright: ignore # noqa:F401
  File "/opt/venv/lib/python3.9/site-packages/pandas/compat/__init__.py", line 18, in <module>
[2024-09-23T09:12:25.457+0000] {docker.py:324} INFO - from pandas.compat.numpy import (
  File "/opt/venv/lib/python3.9/site-packages/pandas/compat/numpy/__init__.py", line 4, in <module>
[2024-09-23T09:12:25.457+0000] {docker.py:324} INFO - from pandas.util.version import Version
  File "/opt/venv/lib/python3.9/site-packages/pandas/util/__init__.py", line 2, in <module>
[2024-09-23T09:12:25.457+0000] {docker.py:324} INFO - from pandas.util._decorators import (  # noqa:F401
  File "/opt/venv/lib/python3.9/site-packages/pandas/util/_decorators.py", line 14, in <module>
[2024-09-23T09:12:25.457+0000] {docker.py:324} INFO - from pandas._libs.properties import cache_readonly
  File "/opt/venv/lib/python3.9/site-packages/pandas/_libs/__init__.py", line 13, in <module>
[2024-09-23T09:12:25.458+0000] {docker.py:324} INFO - from pandas._libs.interval import Interval
  File "pandas/_libs/interval.pyx", line 1, in init pandas._libs.interval
[2024-09-23T09:12:25.458+0000] {docker.py:324} INFO - ValueError: numpy.dtype size changed, may indicate binary incompatibility. Expected 96 from C header, got 88 from PyObject
[2024-09-23T09:12:25.657+0000] {taskinstance.py:1902} ERROR - Task failed with exception
Traceback (most recent call last):
  File "/home/airflow/.local/lib/python3.7/site-packages/docker/api/client.py", line 268, in _raise_for_status
    response.raise_for_status()
  File "/home/airflow/.local/lib/python3.7/site-packages/requests/models.py", line 1022, in raise_for_status
    raise HTTPError(http_error_msg, response=self)
requests.exceptions.HTTPError: 400 Client Error: Bad Request for url: http+docker://localhost/v1.47/containers/create

The above exception was the direct cause of the following exception:

Traceback (most recent call last):
  File "/home/airflow/.local/lib/python3.7/site-packages/airflow/providers/docker/operators/docker.py", line 269, in _run_image
    return self._run_image_with_mounts(self.mounts + [tmp_mount], add_tmp_variable=True)
  File "/home/airflow/.local/lib/python3.7/site-packages/airflow/providers/docker/operators/docker.py", line 314, in _run_image_with_mounts
    tty=self.tty,
  File "/home/airflow/.local/lib/python3.7/site-packages/docker/api/container.py", line 431, in create_container
    return self.create_container_from_config(config, name, platform)
  File "/home/airflow/.local/lib/python3.7/site-packages/docker/api/container.py", line 448, in create_container_from_config
    return self._result(res, True)
  File "/home/airflow/.local/lib/python3.7/site-packages/docker/api/client.py", line 274, in _result
    self._raise_for_status(response)
  File "/home/airflow/.local/lib/python3.7/site-packages/docker/api/client.py", line 270, in _raise_for_status
    raise create_api_error_from_http_exception(e) from e
  File "/home/airflow/.local/lib/python3.7/site-packages/docker/errors.py", line 39, in create_api_error_from_http_exception
    raise cls(e, response=response, explanation=explanation) from e
docker.errors.APIError: 400 Client Error for http+docker://localhost/v1.47/containers/create: Bad Request ("invalid mount config for type "bind": bind source path does not exist: /tmp/airflowtmpnm65qg4d")

During handling of the above exception, another exception occurred:

Traceback (most recent call last):
  File "/home/airflow/.local/lib/python3.7/site-packages/airflow/providers/docker/operators/docker.py", line 400, in execute
    return self._run_image()
  File "/home/airflow/.local/lib/python3.7/site-packages/airflow/providers/docker/operators/docker.py", line 278, in _run_image
    return self._run_image_with_mounts(self.mounts, add_tmp_variable=False)
  File "/home/airflow/.local/lib/python3.7/site-packages/airflow/providers/docker/operators/docker.py", line 329, in _run_image_with_mounts
    raise AirflowException(f'Docker container failed: {repr(result)} lines {joined_log_lines}')
airflow.exceptions.AirflowException: Docker container failed: {'StatusCode': 1} lines Traceback (most recent call last):
  File "/opt/venv/bin/feast", line 5, in <module>
from feast.cli import cli
File "/opt/venv/lib/python3.9/site-packages/feast/__init__.py", line 7, in <module>
from feast.infra.offline_stores.bigquery_source import BigQuerySource
  File "/opt/venv/lib/python3.9/site-packages/feast/infra/offline_stores/bigquery_source.py", line 5, in <module>
from feast import type_map
  File "/opt/venv/lib/python3.9/site-packages/feast/type_map.py", line 34, in <module>
import pandas as pd
  File "/opt/venv/lib/python3.9/site-packages/pandas/__init__.py", line 22, in <module>
from pandas.compat import is_numpy_dev as _is_numpy_dev  # pyright: ignore # noqa:F401
  File "/opt/venv/lib/python3.9/site-packages/pandas/compat/__init__.py", line 18, in <module>
from pandas.compat.numpy import (
  File "/opt/venv/lib/python3.9/site-packages/pandas/compat/numpy/__init__.py", line 4, in <module>
from pandas.util.version import Version
  File "/opt/venv/lib/python3.9/site-packages/pandas/util/__init__.py", line 2, in <module>
from pandas.util._decorators import (  # noqa:F401
  File "/opt/venv/lib/python3.9/site-packages/pandas/util/_decorators.py", line 14, in <module>
from pandas._libs.properties import cache_readonly
  File "/opt/venv/lib/python3.9/site-packages/pandas/_libs/__init__.py", line 13, in <module>
from pandas._libs.interval import Interval
  File "pandas/_libs/interval.pyx", line 1, in init pandas._libs.interval
ValueError: numpy.dtype size changed, may indicate binary incompatibility. Expected 96 from C header, got 88 from PyObject
[2024-09-23T09:12:25.662+0000] {taskinstance.py:1412} INFO - Marking task as FAILED. dag_id=materlize_offline_to_online, task_id=materialize_task, execution_date=20220101T000000, start_date=20240923T091223, end_date=20240923T091225
[2024-09-23T09:12:25.676+0000] {standard_task_runner.py:97} ERROR - Failed to execute job 113 for task materialize_task (Docker container failed: {'StatusCode': 1} lines Traceback (most recent call last):
  File "/opt/venv/bin/feast", line 5, in <module>
from feast.cli import cli
File "/opt/venv/lib/python3.9/site-packages/feast/__init__.py", line 7, in <module>
from feast.infra.offline_stores.bigquery_source import BigQuerySource
  File "/opt/venv/lib/python3.9/site-packages/feast/infra/offline_stores/bigquery_source.py", line 5, in <module>
from feast import type_map
  File "/opt/venv/lib/python3.9/site-packages/feast/type_map.py", line 34, in <module>
import pandas as pd
  File "/opt/venv/lib/python3.9/site-packages/pandas/__init__.py", line 22, in <module>
from pandas.compat import is_numpy_dev as _is_numpy_dev  # pyright: ignore # noqa:F401
  File "/opt/venv/lib/python3.9/site-packages/pandas/compat/__init__.py", line 18, in <module>
from pandas.compat.numpy import (
  File "/opt/venv/lib/python3.9/site-packages/pandas/compat/numpy/__init__.py", line 4, in <module>
from pandas.util.version import Version
  File "/opt/venv/lib/python3.9/site-packages/pandas/util/__init__.py", line 2, in <module>
from pandas.util._decorators import (  # noqa:F401
  File "/opt/venv/lib/python3.9/site-packages/pandas/util/_decorators.py", line 14, in <module>
from pandas._libs.properties import cache_readonly
  File "/opt/venv/lib/python3.9/site-packages/pandas/_libs/__init__.py", line 13, in <module>
from pandas._libs.interval import Interval
  File "pandas/_libs/interval.pyx", line 1, in init pandas._libs.interval
ValueError: numpy.dtype size changed, may indicate binary incompatibility. Expected 96 from C header, got 88 from PyObject; 713)
[2024-09-23T09:12:25.715+0000] {local_task_job.py:156} INFO - Task exited with return code 1
[2024-09-23T09:12:25.782+0000] {local_task_job.py:279} INFO - 0 downstream tasks scheduled from follow-on schedule check
[2024-10-16T07:06:24.270+0000] {taskinstance.py:1171} INFO - Dependencies all met for <TaskInstance: materlize_offline_to_online.materialize_task scheduled__2022-01-01T00:00:00+00:00 [queued]>
[2024-10-16T07:06:24.408+0000] {taskinstance.py:1171} INFO - Dependencies all met for <TaskInstance: materlize_offline_to_online.materialize_task scheduled__2022-01-01T00:00:00+00:00 [queued]>
[2024-10-16T07:06:24.408+0000] {taskinstance.py:1368} INFO - 
--------------------------------------------------------------------------------
[2024-10-16T07:06:24.409+0000] {taskinstance.py:1369} INFO - Starting attempt 1 of 1
[2024-10-16T07:06:24.410+0000] {taskinstance.py:1370} INFO - 
--------------------------------------------------------------------------------
[2024-10-16T07:06:24.432+0000] {taskinstance.py:1389} INFO - Executing <Task(DockerOperator): materialize_task> on 2022-01-01 00:00:00+00:00
[2024-10-16T07:06:24.438+0000] {standard_task_runner.py:52} INFO - Started process 395 to run task
[2024-10-16T07:06:24.442+0000] {standard_task_runner.py:79} INFO - Running: ['***', 'tasks', 'run', 'materlize_offline_to_online', 'materialize_task', 'scheduled__2022-01-01T00:00:00+00:00', '--job-id', '10', '--raw', '--subdir', 'DAGS_FOLDER/data_pipeline/materialize_offline_to_online.py', '--cfg-path', '/tmp/tmp62awhuqe', '--error-file', '/tmp/tmpgqxk4nkt']
[2024-10-16T07:06:24.444+0000] {standard_task_runner.py:80} INFO - Job 10: Subtask materialize_task
[2024-10-16T07:06:24.510+0000] {task_command.py:371} INFO - Running <TaskInstance: materlize_offline_to_online.materialize_task scheduled__2022-01-01T00:00:00+00:00 [running]> on host bc2dbf4723f9
[2024-10-16T07:06:24.586+0000] {taskinstance.py:1583} INFO - Exporting the following env vars:
AIRFLOW_CTX_DAG_OWNER=mlopsvn
AIRFLOW_CTX_DAG_ID=materlize_offline_to_online
AIRFLOW_CTX_TASK_ID=materialize_task
AIRFLOW_CTX_EXECUTION_DATE=2022-01-01T00:00:00+00:00
AIRFLOW_CTX_TRY_NUMBER=1
AIRFLOW_CTX_DAG_RUN_ID=scheduled__2022-01-01T00:00:00+00:00
[2024-10-16T07:06:24.603+0000] {docker.py:262} INFO - Starting docker container from image mlopsvn/mlops_crash_course/data_pipeline:latest
[2024-10-16T07:06:24.605+0000] {docker.py:273} WARNING - Using remote engine or docker-in-docker and mounting temporary volume from host is not supported. Falling back to `mount_tmp_dir=False` mode. You can set `mount_tmp_dir` parameter to False to disable mounting and remove the warning
[2024-10-16T07:06:27.803+0000] {docker.py:324} INFO - /opt/venv/lib/python3.9/site-packages/feast/repo_config.py:207: RuntimeWarning: `entity_key_serialization_version` is either not specified in the feature_store.yaml, or is specified to a value <= 1.This serialization version may cause errors when trying to write fields with the `Long` data type into the online store. Specifying `entity_key_serialization_version` to 2 is recommended for new projects. 
  warnings.warn(
[2024-10-16T07:06:27.853+0000] {docker.py:324} INFO - /opt/venv/lib/python3.9/site-packages/feast/stream_feature_view.py:93: RuntimeWarning: Stream feature views are experimental features in alpha development. Some functionality may still be unstable so functionality can change in the future.
  warnings.warn(
[2024-10-16T07:06:27.948+0000] {docker.py:324} INFO - Feast is an open source project that collects anonymized error reporting and usage statistics. To opt out or learn more see https://docs.feast.dev/reference/usage
Materializing [1m[32m2[0m feature views to [1m[32m2024-10-16 00:00:00+00:00[0m into the [1m[32mredis[0m online store.

[1m[32mdriver_stats[0m from [1m[32m2024-09-23 00:00:00+00:00[0m to [1m[32m2024-10-16 00:00:00+00:00[0m:
[2024-10-16T07:06:27.948+0000] {docker.py:324} INFO - 0it [00:00, ?it/s]0it [00:00, ?it/s]
[2024-10-16T07:06:28.066+0000] {docker.py:324} INFO - [1m[32mdriver_stats_stream[0m from [1m[32m2024-09-23 00:00:00+00:00[0m to [1m[32m2024-10-16 00:00:00+00:00[0m:
[2024-10-16T07:06:28.067+0000] {docker.py:324} INFO - 0it [00:00, ?it/s]
[2024-10-16T07:06:28.067+0000] {docker.py:324} INFO - 0it [00:00, ?it/s]
[2024-10-16T07:06:28.068+0000] {docker.py:324} INFO - /opt/venv/lib/python3.9/site-packages/feast/stream_feature_view.py:93: RuntimeWarning: Stream feature views are experimental features in alpha development. Some functionality may still be unstable so functionality can change in the future.
  warnings.warn(
[2024-10-16T07:06:28.517+0000] {taskinstance.py:1412} INFO - Marking task as SUCCESS. dag_id=materlize_offline_to_online, task_id=materialize_task, execution_date=20220101T000000, start_date=20241016T070624, end_date=20241016T070628
[2024-10-16T07:06:28.557+0000] {local_task_job.py:156} INFO - Task exited with return code 0
[2024-10-16T07:06:28.588+0000] {local_task_job.py:279} INFO - 0 downstream tasks scheduled from follow-on schedule check
